Workbook

Sheet CEO_PANEL
A1: ADEZO OS 2.0 | CEO PANEL
A2: Luxury sales operating system — wynik, ryzyko i premie.
A4: PIPELINE | D4: FORECAST | G4: SPRZEDAŻ NETTO | J4: ALERTY KRYTYCZNE
A7: PIPELINE | D7: FORECAST | G7: SPRZEDA NETTO | J7: ALERTY KRYTYCZNE
A8: 3487048 | D8: 382100 | G8: 511825.12 | J8: 591
A10: MAGDA SCOREBOARD | F10: NAJWAŻNIEJSZE ALERTY
A11: Handlowiec | B11: Sprzedaż | C11: Forecast | D11: =SUM(_FORECAST_CALC!$N:$N) -> 0 | F11: Waga | G11: Klient | H11: Oferta | I11: Komunikat
A12: =MAGDA_SCOREBOARD!A5 -> MAGDA K | B12: =IFERROR(MAGDA_SCOREBOARD!B5,0) -> 290418 | C12: =MAGDA_SCOREBOARD!E5 -> 5808.36 | D12: =IFERROR(MAGDA_SCOREBOARD!M5,0) -> 18000 | F12: WYSOKA | G12: Wrocław | H12: 5443 | I12: Brak statusu utrudnia kontrolę pipeline.
A13: =MAGDA_SCOREBOARD!A6 -> MAGDA B | B13: =IFERROR(MAGDA_SCOREBOARD!B6,0) -> 221407.12 | C13: =MAGDA_SCOREBOARD!E6 -> 4428.14 | D13: =IFERROR(MAGDA_SCOREBOARD!M6,0) -> 364100 | F13: KRYTYCZNA | G13: Wrocław | H13: 5443 | I13: Brak kontaktu 158 dni.
F14: WYSOKA | G14: (brak klienta) | H14: 5453 | I14: Oferta bez kwoty blokuje forecast.
F15: WYSOKA | G15: (brak klienta) | H15: 5453 | I15: Brak statusu utrudnia kontrolę pipeline.
A16: FOLLOW-UP 3D | B16: 154 | D16: FOLLOW-UP 7D | E16: 152 | F16: KRYTYCZNA | G16: FOLLOW-UP 30D | H16: 129 | I16: Brak kontaktu 151 dni. | J16: REAKTYWACJE 90D | K16: 113
F17: WYSOKA | G17: (brak klienta) | H17: 5455 | I17: Brak statusu utrudnia kontrolę pipeline.
A18: POZARY A | B18: 25 | D18: POZARY B | E18: 72 | G18: POZARY C | H18: 0 | I18: Brak kontaktu 148 dni.
A19: WARTOSC POZAROW A | B19: 1026948 | D19: WARTOSC POZAROW B | E19: 1783800 | G19: WARTOSC POZAROW C | H19: 0 | I19: Brak statusu utrudnia kontrolę pipeline.
A21: PREMIA MAGDA K | B21: 5308.36 | D21: PREMIA MAGDA B | E21: 3928.14
A22: SPRZEDAZ MAGDA K | B22: 290418 | D22: SPRZEDAZ MAGDA B | E22: 221407.12
A23: POZARY A MAGDA K | B23: 14 | D23: POZARY A MAGDA B | E23: 11
A24: POZARY B MAGDA K | B24: 40 | D24: POZARY B MAGDA B | E24: 32
A26: EXECUTIVE DAILY BRIEF PRO
A27: PIPELINE | B27: 3487048
A28: FORECAST | B28: 382100
A29: SPRZEDAZ | B29: 511825.12
A30: PREMIA K | B30: 5308.36
A31: PREMIA B | B31: 3928.14
A32: POZARY A | B32: 25
A33: POZARY B | B33: 73
A34: ALERTY | B34: 591

Sheet CRM_MAGDY
A1: ADEZO CRM MAGDY
A2: Roboczy CRM. Uzupełniaj po każdym kontakcie. Czerwone pola oznaczają braki blokujące ADEZO OS.
A4: DATA ZAPYTANIA | B4: DATA OFERTY | C4: DATA OSTATNIEJ AKCJI | D4: DATA KOLEJNEGO KONTAKTU | E4: KLIENT | F4: E-MAIL | G4: TELEFON | H4: NR OFERTY | I4: OBSŁUGA | J4: ŹRÓDŁO | K4: KWOTA | L4: SZANSA % | M4: KAMIEŃ MILOWY | N4: STATUS | O4: DATA SPRZEDAŻY | P4: SPRZEDAŻ NETTO | Q4: SPRZEDANE SZTUKI | R4: MIEJSCOWOŚĆ | S4: POWÓD ODRZUCENIA | T4: NOTATKI | U4: DNI OD AKCJI | V4: JAKOŚĆ CRM % | W4: SYGNAŁ OS
A5: 46014 | B5: 46024 | C5: 46024 | H5: 5443 | I5: Magda K | J5: MAIL | K5: 28000 | M5: follow up | R5: Wrocław | U5: =IF(C5="","",TODAY()-C5) -> 162 | V5: 0 | W5: BRAKI CRM
A6: 46024 | B6: 46023.829 | C6: 46024 | H6: 5444 | I6: Magda K | J6: FACEBOOK | K6: 26622 | L6: 1 | M6: zamówienie | N6: WYGRANA | O6: 46163 | P6: 26622 | Q6: 1 | R6: Borzechów | U6: =IF(C6="","",TODAY()-C6) -> 162 | V6: 0.5 | W6: BRAKI CRM
A7: 46024 | B7: 46024 | C7: 46024 | H7: 5445 | I7: Magda K | J7: INSTAGRAM | K7: 23000 | M7: follow up | N7: PRZEGRANA | R7: Stara Niedziałka 05-300 | S7: nie odpowiada | T7: instagram pejtiiii | U7: =IF(C7="","",TODAY()-C7) -> 162 | V7: 0.25 | W7: BRAKI CRM
A8: 46026 | B8: 46027 | C8: 46027 | H8: 5446 | I8: Magda K | J8: MAIL | M8: follow up | N8: PRZEGRANA | S8: nie odpowiada | U8: =IF(C8="","",TODAY()-C8) -> 159 | V8: 0.25 | W8: BRAKI CRM
A9: 46027 | B9: 46027 | C9: 46027 | H9: 5447 | I9: Magda K | J9: MAIL | K9: 21000 | M9: follow up | N9: PRZEGRANA | R9: Lubiszew Tczewski | S9: nie odpowiada | U9: =IF(C9="","",TODAY()-C9) -> 159 | V9: 0.25 | W9: BRAKI CRM
A10: 46023 | B10: 46027 | C10: 46027 | H10: 5448 | I10: Magda K | J10: INSTAGRAM | K10: 23000 | M10: follow up | N10: PRZEGRANA | R10: Tarchały Wielkie | S10: nie odpowiada | U10: =IF(C10="","",TODAY()-C10) -> 159 | V10: 0.25 | W10: BRAKI CRM
A11: 46013 | B11: 46029 | C11: 46029 | H11: 5449 | I11: Magda K | J11: FACEBOOK | K11: 20500 | M11: follow up | N11: PRZEGRANA | R11: Łososina Dolna | S11: nie odpowiada | U11: =IF(C11="","",TODAY()-C11) -> 157 | V11: 0.25 | W11: BRAKI CRM
A12: 46027 | B12: 46029 | C12: 46029 | H12: 5450 | I12: Magda K | J12: FACEBOOK | K12: 29000 | M12: follow up | N12: PRZEGRANA | R12: Tarnowo podgórne | S12: nie odpowiada | U12: =IF(C12="","",TODAY()-C12) -> 157 | V12: 0.25 | W12: BRAKI CRM
A13: 46027 | B13: 46029 | C13: 46029 | H13: 5451 | I13: Magda K | J13: FACEBOOK | K13: 21000 | M13: follow up | N13: PRZEGRANA | R13: Nowe Rybie | S13: nie odpowiada | U13: =IF(C13="","",TODAY()-C13) -> 157 | V13: 0.25 | W13: BRAKI CRM
A14: 46027 | B14: 46030 | C14: 46030 | H14: 5452 | I14: Magda K | J14: MAIL | K14: 23000 | M14: oferta | N14: PRZEGRANA | R14: Bielsko Biała | S14: nie odpowiada | U14: =IF(C14="","",TODAY()-C14) -> 156 | V14: 0.25 | W14: BRAKI CRM
A15: 46031 | B15: 46031 | C15: 46031 | H15: 5453 | I15: Magda B | J15: MAIL | T15: salon | U15: =IF(C15="","",TODAY()-C15) -> 155 | V15: 0 | W15: BRAKI CRM
A16: 46034 | B16: 46034 | C16: 46034 | H16: 5454 | I16: Magda K | J16: FORMULARZ | K16: 23000 | M16: wstępne rozmowy | N16: PRZEGRANA | S16: nie odpowiada | U16: =IF(C16="","",TODAY()-C16) -> 152 | V16: 0.25 | W16: BRAKI CRM
A17: 46034 | B17: 46034 | C17: 46034 | H17: 5455 | I17: Magda B | J17: MAIL | K17: 23000 | M17: oferta | U17: =IF(C17="","",TODAY()-C17) -> 152 | V17: 0 | W17: BRAKI CRM
A18: 46034 | B18: 46034 | C18: 46034 | H18: 5456 | I18: Magda K | J18: MAIL | K18: 20196 | L18: 1 | M18: realizacja | N18: WYGRANA | O18: 46162 | P18: 20196 | Q18: 1 | R18: Krakó | U18: =IF(C18="","",TODAY()-C18) -> 152 | V18: 0.5 | W18: BRAKI CRM
A19: 46035 | B19: 46035 | C19: 46035 | H19: 5457 | I19: Magda K | J19: MAIL | K19: 21000 | M19: follow up | R19: Głodowo | S19: wysoka cena | U19: =IF(C19="","",TODAY()-C19) -> 151 | V19: 0 | W19: BRAKI CRM
A20: 46035 | B20: 46035 | C20: 46035 | H20: 5458 | I20: Magda B | J20: MAIL | K20: 18252 | L20: 1 | M20: realizacja | N20: WYGRANA | P20: 18252 | Q20: 1 | U20: =IF(C20="","",TODAY()-C20) -> 151 | V20: 0.5 | W20: BRAKI CRM
A21: 46036 | B21: 46036 | C21: 46036 | H21: 5459 | I21: Magda B | J21: MAIL | K21: 25000 | M21: oferta | T21: Józef Żurek | U21: =IF(C21="","",TODAY()-C21) -> 150 | V21: 0 | W21: BRAKI CRM
A22: 46036 | B22: 46036 | C22: 46036 | H22: 5460 | I22: Magda B | J22: MAIL | K22: 20000 | M22: oferta | U22: =IF(C22="","",TODAY()-C22) -> 150 | V22: 0 | W22: BRAKI CRM
A23: 46037 | B23: 46037 | C23: 46037 | H23: 5461 | I23: Magda K | J23: FACEBOOK | K23: 23000 | M23: follow up | N23: PRZEGRANA | R23: Podłęże | S23: nie odpowiada | U23: =IF(C23="","",TODAY()-C23) -> 149 | V23: 0.25 | W23: BRAKI CRM
A24: 46037 | B24: 46037 | C24: 46037 | H24: 5462 | I24: Magda K | J24: FACEBOOK | K24: 22000 | M24: follow up | N24: PRZEGRANA | S24: nie odpowiada | U24: =IF(C24="","",TODAY()-C24) -> 149 | V24: 0.25 | W24: BRAKI CRM
A25: 45307 | B25: 46038 | C25: 46038 | H25: 5463 | I25: Magda B | J25: MAIL | K25: 25100 | M25: oferta | R25: Rzeszów | U25: =IF(C25="","",TODAY()-C25) -> 148 | V25: 0 | W25: BRAKI CRM
A26: 46038 | B26: 46038 | C26: 46038 | H26: 5464 | I26: Magda K | J26: MAIL | K26: 12500 | M26: widełki cenowe | N26: PRZEGRANA | S26: nie odpowiada | T26: czekamy na miejscowosc | U26: =IF(C26="","",TODAY()-C26) -> 148 | V26: 0.25 | W26: BRAKI CRM
A27: 46038 | B27: 46038 | C27: 46038 | H27: 5465 | I27: Magda K | J27: MAIL | K27: 25600 | L27: 1 | M27: decyzja na tak | N27: WYGRANA | P27: 25600 | Q27: 1 | R27: Grabowo 07-415 | T27: bedzie zamawiac, czekaja na wylewki | U27: =IF(C27="","",TODAY()-C27) -> 148 | V27: 0.5 | W27: BRAKI CRM
A28: 46038 | B28: 46038 | C28: 46038 | H28: 5466 | I28: Magda B | J28: TELEFON | K28: 50000 | M28: oferta | R28: Konstancin Jeziorna | U28: =IF(C28="","",TODAY()-C28) -> 148 | V28: 0 | W28: BRAKI CRM
A29: 46038 | B29: 46038 | C29: 46038 | H29: 5467 | I29: Magda B | J29: FORMULARZ | K29: 12000 | M29: widełki cenowe | U29: =IF(C29="","",TODAY()-C29) -> 148 | V29: 0 | W29: BRAKI CRM
A30: 46041 | B30: 46041 | C30: 46041 | H30: 5468 | I30: Magda B | J30: MAIL | K30: 20000 | M30: oferta | R30: Holandia | U30: =IF(C30="","",TODAY()-C30) -> 145 | V30: 0 | W30: BRAKI CRM
A31: 46041 | B31: 46041 | C31: 46041 | H31: 5469 | I31: Magda B | J31: FORMULARZ | K31: 25000 | M31: oferta | R31: Częstochowa | U31: =IF(C31="","",TODAY()-C31) -> 145 | V31: 0 | W31: BRAKI CRM
A32: 46041 | B32: 46041 | C32: 46041 | H32: 5470 | I32: Magda B | J32: WIZYTA OSOBISTA | K32: 14000 | L32: 1 | M32: zamówienie | N32: WYGRANA | P32: 14000 | Q32: 1 | R32: Bielsko - Biała | U32: =IF(C32="","",TODAY()-C32) -> 145 | V32: 0.5 | W32: BRAKI CRM
A33: 46041 | B33: 46042 | C33: 46042 | H33: 5471 | I33: Magda K | J33: MAIL | K33: 25000 | M33: follow up | N33: PRZEGRANA | R33: Pruszków | S33: nie odpowiada | U33: =IF(C33="","",TODAY()-C33) -> 144 | V33: 0.25 | W33: BRAKI CRM
A34: 46041 | B34: 46042 | C34: 46042 | H34: 5472 | I34: Magda K | J34: MAIL | K34: 23000 | M34: follow up | N34: PRZEGRANA | R34: Zakliczyn kolo Myslenic | S34: nie odpowiada | U34: =IF(C34="","",TODAY()-C34) -> 144 | V34: 0.25 | W34: BRAKI CRM
A35: 46042 | B35: 46042 | C35: 46042 | H35: 5473 | I35: Magda K | J35: MAIL | K35: 25000 | M35: follow up | N35: PRZEGRANA | R35: Tczew | S35: nie odpowiada | T35: dostawa | U35: =IF(C35="","",TODAY()-C35) -> 144 | V35: 0.25 | W35: BRAKI CRM
A36: 46034 | B36: 46043 | C36: 46043 | H36: 5474 | I36: Magda K | J36: MAIL | K36: 23000 | M36: follow up | N36: PRZEGRANA | R36: Jakubowice Koninskie | S36: nie odpowiada | U36: =IF(C36="","",TODAY()-C36) -> 143 | V36: 0.25 | W36: BRAKI CRM
A37: 46027 | B37: 46043 | C37: 46043 | H37: 5475 | I37: Magda K | J37: MAIL | K37: 26000 | M37: oferta | N37: PRZEGRANA | R37: Lubiszewo Tczewskie | S37: nie odpowiada | U37: =IF(C37="","",TODAY()-C37) -> 143 | V37: 0.25 | W37: BRAKI CRM
A38: 46044 | B38: 46045 | C38: 46045 | H38: 5476 | I38: Magda K | J38: MAIL | K38: 19000 | M38: follow up | N38: PRZEGRANA | R38: Wyszków | S38: wysoka cena | T38: kupiła baranskiego | U38: =IF(C38="","",TODAY()-C38) -> 141 | V38: 0.25 | W38: BRAKI CRM
A39: 46042 | B39: 46045 | C39: 46045 | H39: 5477 | I39: Magda K | J39: MAIL | K39: 23000 | M39: follow up | N39: PRZEGRANA | R39: Krosno | S39: nie odpowiada | T39: budzet 17 000 zł, wysłana wersja ekonomiczna | U39: =IF(C39="","",TODAY()-C39) -> 141 | V39: 0.25 | W39: BRAKI CRM
A40: 45680 | B40: 45680 | C40: 45680 | H40: 5478 | I40: Magda B | J40: TELEFON | K40: 30000 | M40: oferta | R40: Rzeszów | T40: będzie zamawiał czeka na wylewki | U40: =IF(C40="","",TODAY()-C40) -> 506 | V40: 0 | W40: BRAKI CRM
A41: 46048 | B41: 46048 | C41: 46048 | H41: 5479 | I41: Magda B | J41: FORMULARZ | K41: 25000 | M41: oferta | U41: =IF(C41="","",TODAY()-C41) -> 138 | V41: 0 | W41: BRAKI CRM
...

Sheet MOJE_ZADANIA_MAGDA_K
A1: ADEZO OS | MOJE_ZADANIA_MAGDA_K
A2: Widok roboczy. Zadzwoń, zaktualizuj CRM_MAGDY i oznacz status zadania.
A4: TERMIN | B4: KLIENT | C4: NR OFERTY | D4: TYP ZADANIA | E4: PRIORYTET | F4: DNI PO TERMINIE | G4: STATUS | H4: NOTATKA MAGDY | I4: AKCJA
A5: 46182 | B5: Wrocław | C5: 5443 | D5: BRAK_STATUSU | E5: WYSOKI | F5: =IF(A5="","",MAX(0,TODAY()-A5)) -> 4 | G5: DO ZROBIENIA | H5: Uzupełnij status.
A6: 46182 | B6: Wrocław | C6: 5443 | D6: BRAK_SZANSY | E6: ŚREDNI | F6: =IF(A6="","",MAX(0,TODAY()-A6)) -> 4 | G6: DO ZROBIENIA | H6: Uzupełnij szansę sprzedaży.
A7: 46182 | B7: Wrocław | C7: 5443 | D7: REAKTYWACJA_90D | E7: KRYTYCZNY | F7: =IF(A7="","",MAX(0,TODAY()-A7)) -> 4 | G7: DO ZROBIENIA | H7: Zimny lead — reaktywacja albo zamknięcie.
A8: 46182 | B8: Głodowo | C8: 5457 | D8: BRAK_STATUSU | E8: WYSOKI | F8: =IF(A8="","",MAX(0,TODAY()-A8)) -> 4 | G8: DO ZROBIENIA | H8: Uzupełnij status.
A9: 46182 | B9: Głodowo | C9: 5457 | D9: BRAK_SZANSY | E9: ŚREDNI | F9: =IF(A9="","",MAX(0,TODAY()-A9)) -> 4 | G9: DO ZROBIENIA | H9: Uzupełnij szansę sprzedaży.
A10: 46182 | B10: Głodowo | C10: 5457 | D10: REAKTYWACJA_90D | E10: KRYTYCZNY | F10: =IF(A10="","",MAX(0,TODAY()-A10)) -> 4 | G10: DO ZROBIENIA | H10: Zimny lead — reaktywacja albo zamknięcie.
A11: 46182 | B11: POznan | C11: 5480 | D11: BRAK_STATUSU | E11: WYSOKI | F11: =IF(A11="","",MAX(0,TODAY()-A11)) -> 4 | G11: DO ZROBIENIA | H11: Uzupełnij status.
A12: 46182 | B12: POznan | C12: 5480 | D12: BRAK_SZANSY | E12: ŚREDNI | F12: =IF(A12="","",MAX(0,TODAY()-A12)) -> 4 | G12: DO ZROBIENIA | H12: Uzupełnij szansę sprzedaży.
A13: 46182 | B13: POznan | C13: 5480 | D13: REAKTYWACJA_90D | E13: KRYTYCZNY | F13: =IF(A13="","",MAX(0,TODAY()-A13)) -> 4 | G13: DO ZROBIENIA | H13: Zimny lead — reaktywacja albo zamknięcie.
A14: 46182 | B14: Pszczyna | C14: 5494 | D14: BRAK_STATUSU | E14: WYSOKI | F14: =IF(A14="","",MAX(0,TODAY()-A14)) -> 4 | G14: DO ZROBIENIA | H14: Uzupełnij status.
A15: 46182 | B15: Pszczyna | C15: 5494 | D15: BRAK_SZANSY | E15: ŚREDNI | F15: =IF(A15="","",MAX(0,TODAY()-A15)) -> 4 | G15: DO ZROBIENIA | H15: Uzupełnij szansę sprzedaży.
A16: 46182 | B16: Pszczyna | C16: 5494 | D16: REAKTYWACJA_90D | E16: KRYTYCZNY | F16: =IF(A16="","",MAX(0,TODAY()-A16)) -> 4 | G16: DO ZROBIENIA | H16: Zimny lead — reaktywacja albo zamknięcie.
... A304: 46182 | B304: (brak klienta) | C304: 5665 | D304: BRAK_STATUSU | E304: WYSOKI | F304: =IF(A304="","",MAX(0,TODAY()-A304)) -> 4 | G304: DO ZROBIENIA | H304: Uzupełnij status.
B500: (brak klienta) | C500: 5443 | D500: FOLLOW-UP 3D | E500: ŚREDNI | F500: 159 | G500: DO ZROBIENIA | H500: Automat follow-up: FOLLOW-UP 3D
B501: (brak klienta) | C501: 5443 | D501: FOLLOW-UP 7D | E501: WYSOKI | F501: 159 | G501: DO ZROBIENIA | H501: Automat follow-up: FOLLOW-UP 7D
B502: (brak klienta) | C502: 5443 | D502: FOLLOW-UP 30D | E502: KRYTYCZNY | F502: 159 | G502: DO ZROBIENIA | H502: Automat follow-up: FOLLOW-UP 30D
B503: (brak klienta) | C503: 5443 | D503: REAKTYWACJA 90D | E503: KRYTYCZNY | F503: 159 | G503: DO ZROBIENIA | H503: Automat follow-up: REAKTYWACJA 90D
B504: (brak klienta) | C504: 5457 | D504: FOLLOW-UP 3D | E504: ŚREDNI | F504: 148 | G504: DO ZROBIENIA | H504: Automat follow-up: FOLLOW-UP 3D
B505: (brak klienta) | C505: 5457 | D505: FOLLOW-UP 7D | E505: WYSOKI | F505: 148 | G505: DO ZROBIENIA | H505: Automat follow-up: FOLLOW-UP 7D
B506: (brak klienta) | C506: 5457 | D506: FOLLOW-UP 30D | E506: KRYTYCZNY | F506: 148 | G506: DO ZROBIENIA | H506: Automat follow-up: FOLLOW-UP 30D
B507: (brak klienta) | C507: 5457 | D507: REAKTYWACJA 90D | E507: KRYTYCZNY | F507: 148 | G507: DO ZROBIENIA | H507: Automat follow-up: REAKTYWACJA 90D
B508: (brak klienta) | C508: 5480 | D508: FOLLOW-UP 3D | E508: ŚREDNI | F508: 135 | G508: DO ZROBIENIA | H508: Automat follow-up: FOLLOW-UP 3D
B509: (brak klienta) | C509: 5480 | D509: FOLLOW-UP 7D | E509: WYSOKI | F509: 135 | G509: DO ZROBIENIA | H509: Automat follow-up: FOLLOW-UP 7D
B510: (brak klienta) | C510: 5480 | D510: FOLLOW-UP 30D | E510: KRYTYCZNY | F510: 135 | G510: DO ZROBIENIA | H510: Automat follow-up: FOLLOW-UP 30D
B511: (brak klienta) | C511: 5480 | D511: REAKTYWACJA 90D | E511: KRYTYCZNY | F511: 135 | G511: DO ZROBIENIA | H511: Automat follow-up: REAKTYWACJA 90D
... B771: Jarosław Malinowski | C771: 5315 | D771: REAKTYWACJA 90D | E771: KRYTYCZNY | F771: 258 | G771: DO ZROBIENIA | H771: Automat follow-up: REAKTYWACJA 90D

Sheet SYSTEM_HEALTH
A1: SYSTEM_HEALTH
A2: RELEASE_VERSION | B2: ADEZO_OS_2_0_BUILD034G_CLEAN_DROPDOWN_READY
A3: SOURCE_BASE | B3: BUILD034E + dropdowny/logika z V6
A4: STATUS | B4: READY_FOR_OS_2_0_TRUTH_CHECK
A5: CRM_CLEANUP_STATUS | B5: CRM CLEANUP COMPLETE

Sheet MOJE_ZADANIA_MAGDA_B
A1: ADEZO OS | MOJE_ZADANIA_MAGDA_B
A2: Widok roboczy. Zadzwoń, zaktualizuj CRM_MAGDY i oznacz status zadania.
A4: TERMIN | B4: KLIENT | C4: NR OFERTY | D4: TYP ZADANIA | E4: PRIORYTET | F4: DNI PO TERMINIE | G4: STATUS | H4: NOTATKA MAGDY | I4: AKCJA
A5: 46182 | B5: (brak klienta) | C5: 5453 | D5: BRAK_KWOTY | E5: WYSOKI | F5: =IF(A5="","",MAX(0,TODAY()-A5)) -> 4 | G5: DO ZROBIENIA | H5: Uzupełnij kwotę oferty.
A6: 46182 | B6: (brak klienta) | C6: 5453 | D6: BRAK_STATUSU | E6: WYSOKI | F6: =IF(A6="","",MAX(0,TODAY()-A6)) -> 4 | G6: DO ZROBIENIA | H6: Uzupełnij status.
A7: 46182 | B7: (brak klienta) | C7: 5453 | D7: BRAK_SZANSY | E7: ŚREDNI | F7: =IF(A7="","",MAX(0,TODAY()-A7)) -> 4 | G7: DO ZROBIENIA | H7: Uzupełnij szansę sprzedaży.
A8: 46182 | B8: (brak klienta) | C8: 5453 | D8: REAKTYWACJA_90D | E8: KRYTYCZNY | F8: =IF(A8="","",MAX(0,TODAY()-A8)) -> 4 | G8: DO ZROBIENIA | H8: Zimny lead — reaktywacja albo zamknięcie.
A9: 46182 | B9: (brak klienta) | C9: 5455 | D9: BRAK_STATUSU | E9: WYSOKI | F9: =IF(A9="","",MAX(0,TODAY()-A9)) -> 4 | G9: DO ZROBIENIA | H9: Uzupełnij status.
A10: 46182 | B10: (brak klienta) | C10: 5455 | D10: BRAK_SZANSY | E10: ŚREDNI | F10: =IF(A10="","",MAX(0,TODAY()-A10)) -> 4 | G10: DO ZROBIENIA | H10: Uzupełnij szansę sprzedaży.
A11: 46182 | B11: (brak klienta) | C11: 5455 | D11: REAKTYWACJA_90D | E11: KRYTYCZNY | F11: =IF(A11="","",MAX(0,TODAY()-A11)) -> 4 | G11: DO ZROBIENIA | H11: Zimny lead — reaktywacja albo zamknięcie.
A12: 46182 | B12: (brak klienta) | C12: 5459 | D12: BRAK_STATUSU | E12: WYSOKI | F12: =IF(A12="","",MAX(0,TODAY()-A12)) -> 4 | G12: DO ZROBIENIA | H12: Uzupełnij status.
A13: 46182 | B13: (brak klienta) | C13: 5459 | D13: BRAK_SZANSY | E13: ŚREDNI | F13: =IF(A13="","",MAX(0,TODAY()-A13)) -> 4 | G13: DO ZROBIENIA | H13: Uzupełnij szansę sprzedaży.
A14: 46182 | B14: (brak klienta) | C14: 5459 | D14: REAKTYWACJA_90D | E14: KRYTYCZNY | F14: =IF(A14="","",MAX(0,TODAY()-A14)) -> 4 | G14: DO ZROBIENIA | H14: Zimny lead — reaktywacja albo zamknięcie.
A15: 46182 | B15: (brak klienta) | C15: 5460 | D15: BRAK_STATUSU | E15: WYSOKI | F15: =IF(A15="","",MAX(0,TODAY()-A15)) -> 4 | G15: DO ZROBIENIA | H15: Uzupełnij status.
A16: 46182 | B16: (brak klienta) | C16: 5460 | D16: BRAK_SZANSY | E16: ŚREDNI | F16: =IF(A16="","",MAX(0,TODAY()-A16)) -> 4 | G16: DO ZROBIENIA | H16: Uzupełnij szansę sprzedaży.
... A213: 46182 | B213: Bjorn van Nieuwkerk | C213: 5314 | D213: REAKTYWACJA_90D | E213: KRYTYCZNY | F213: =IF(A213="","",MAX(0,TODAY()-A213)) -> 4 | G213: DO ZROBIENIA | H213: Zimny lead — reaktywacja albo zamknięcie.
B500: (brak klienta) | C500: 5453 | D500: FOLLOW-UP 3D | E500: ŚREDNI | F500: 152 | G500: DO ZROBIENIA | H500: Automat follow-up: FOLLOW-UP 3D
B501: (brak klienta) | C501: 5453 | D501: FOLLOW-UP 7D | E501: WYSOKI | F501: 152 | G501: DO ZROBIENIA | H501: Automat follow-up: FOLLOW-UP 7D
B502: (brak klienta) | C502: 5453 | D502: FOLLOW-UP 30D | E502: KRYTYCZNY | F502: 152 | G502: DO ZROBIENIA | H502: Automat follow-up: FOLLOW-UP 30D
B503: (brak klienta) | C503: 5453 | D503: REAKTYWACJA 90D | E503: KRYTYCZNY | F503: 152 | G503: DO ZROBIENIA | H503: Automat follow-up: REAKTYWACJA 90D
B504: (brak klienta) | C504: 5455 | D504: FOLLOW-UP 3D | E504: ŚREDNI | F504: 149 | G504: DO ZROBIENIA | H504: Automat follow-up: FOLLOW-UP 3D
B505: (brak klienta) | C505: 5455 | D505: FOLLOW-UP 7D | E505: WYSOKI | F505: 149 | G505: DO ZROBIENIA | H505: Automat follow-up: FOLLOW-UP 7D
B506: (brak klienta) | C506: 5455 | D506: FOLLOW-UP 30D | E506: KRYTYCZNY | F506: 149 | G506: DO ZROBIENIA | H506: Automat follow-up: FOLLOW-UP 30D
B507: (brak klienta) | C507: 5455 | D507: REAKTYWACJA 90D | E507: KRYTYCZNY | F507: 149 | G507: DO ZROBIENIA | H507: Automat follow-up: REAKTYWACJA 90D
B508: (brak klienta) | C508: 5459 | D508: FOLLOW-UP 3D | E508: ŚREDNI | F508: 147 | G508: DO ZROBIENIA | H508: Automat follow-up: FOLLOW-UP 3D
B509: (brak klienta) | C509: 5459 | D509: FOLLOW-UP 7D | E509: WYSOKI | F509: 147 | G509: DO ZROBIENIA | H509: Automat follow-up: FOLLOW-UP 7D
B510: (brak klienta) | C510: 5459 | D510: FOLLOW-UP 30D | E510: KRYTYCZNY | F510: 147 | G510: DO ZROBIENIA | H510: Automat follow-up: FOLLOW-UP 30D
B511: (brak klienta) | C511: 5459 | D511: REAKTYWACJA 90D | E511: KRYTYCZNY | F511: 147 | G511: DO ZROBIENIA | H511: Automat follow-up: REAKTYWACJA 90D
... B720: Bjorn van Nieuwkerk | C720: 5314 | D720: REAKTYWACJA 90D | E720: KRYTYCZNY | F720: 258 | G720: DO ZROBIENIA | H720: Automat follow-up: REAKTYWACJA 90D

Sheet CRM_CLEANUP_REPORT
A1: NR OFERTY | B1: OBSLUGA | C1: KLIENT | D1: TELEFON | E1: STATUS | F1: PROBLEM | G1: AKCJA
A2: 5443 | B2: Magda K | F2: BRAK KLIENTA | G2: UZUPELNIC DANE
A3: 5443 | B3: Magda K | F3: BRAK TELEFONU | G3: UZUPELNIC DANE
A4: 5443 | B4: Magda K | F4: BRAK STATUSU | G4: UZUPELNIC DANE
A5: 5443 | B5: Magda K | F5: BRAK SZANSA % | G5: UZUPELNIC DANE
A6: 5444 | B6: Magda K | E6: WYGRANA | F6: BRAK KLIENTA | G6: UZUPELNIC DANE
A7: 5444 | B7: Magda K | E7: WYGRANA | F7: BRAK TELEFONU | G7: UZUPELNIC DANE
A8: 5445 | B8: Magda K | E8: PRZEGRANA | F8: BRAK KLIENTA | G8: UZUPELNIC DANE
A9: 5445 | B9: Magda K | E9: PRZEGRANA | F9: BRAK TELEFONU | G9: UZUPELNIC DANE
A10: 5445 | B10: Magda K | E10: PRZEGRANA | F10: BRAK SZANSA % | G10: UZUPELNIC DANE
A11: 5446 | B11: Magda K | E11: PRZEGRANA | F11: BRAK KLIENTA | G11: UZUPELNIC DANE
A12: 5446 | B12: Magda K | E12: PRZEGRANA | F12: BRAK TELEFONU | G12: UZUPELNIC DANE
A13: 5446 | B13: Magda K | E13: PRZEGRANA | F13: BRAK SZANSA % | G13: UZUPELNIC DANE
A14: 5447 | B14: Magda K | E14: PRZEGRANA | F14: BRAK KLIENTA | G14: UZUPELNIC DANE
A15: 5447 | B15: Magda K | E15: PRZEGRANA | F15: BRAK TELEFONU | G15: UZUPELNIC DANE
A16: 5447 | B16: Magda K | E16: PRZEGRANA | F16: BRAK SZANSA % | G16: UZUPELNIC DANE
A17: 5448 | B17: Magda K | E17: PRZEGRANA | F17: BRAK KLIENTA | G17: UZUPELNIC DANE
... A31: 5452 | B31: Magda K | E31: PRZEGRANA | F31: BRAK SZANSA % | G31: UZUPELNIC DANE
A32: 5453 | B32: Magda B | F32: BRAK KLIENTA | G32: UZUPELNIC DANE
A33: 5453 | B33: Magda B | F33: BRAK TELEFONU | G33: UZUPELNIC DANE
A34: 5453 | B34: Magda B | F34: BRAK STATUSU | G34: UZUPELNIC DANE
A35: 5453 | B35: Magda B | F35: BRAK SZANSA % | G35: UZUPELNIC DANE
A36: 5454 | B36: Magda K | E36: PRZEGRANA | F36: BRAK KLIENTA | G36: UZUPELNIC DANE
A37: 5454 | B37: Magda K | E37: PRZEGRANA | F37: BRAK TELEFONU | G37: UZUPELNIC DANE
A38: 5454 | B38: Magda K | E38: PRZEGRANA | F38: BRAK SZANSA % | G38: UZUPELNIC DANE
A39: 5455 | B39: Magda B | F39: BRAK KLIENTA | G39: UZUPELNIC DANE
A40: 5455 | B40: Magda B | F40: BRAK TELEFONU | G40: UZUPELNIC DANE
A41: 5455 | B41: Magda B | F41: BRAK STATUSU | G41: UZUPELNIC DANE
A42: 5455 | B42: Magda B | F42: BRAK SZANSA % | G42: UZUPELNIC DANE
A43: 5456 | B43: Magda K | E43: WYGRANA | F43: BRAK KLIENTA | G43: UZUPELNIC DANE
A44: 5456 | B44: Magda K | E44: WYGRANA | F44: BRAK TELEFONU | G44: UZUPELNIC DANE
A45: 5457 | B45: Magda K | F45: BRAK KLIENTA | G45: UZUPELNIC DANE
A46: 5457 | B46: Magda K | F46: BRAK TELEFONU | G46: UZUPELNIC DANE
A47: 5457 | B47: Magda K | F47: BRAK STATUSU | G47: UZUPELNIC DANE
A48: 5457 | B48: Magda K | F48: BRAK SZANSA % | G48: UZUPELNIC DANE
A49: 5458 | B49: Magda B | E49: WYGRANA | F49: BRAK KLIENTA | G49: UZUPELNIC DANE
A50: 5458 | B50: Magda B | E50: WYGRANA | F50: BRAK TELEFONU | G50: UZUPELNIC DANE
A51: 5459 | B51: Magda B | F51: BRAK KLIENTA | G51: UZUPELNIC DANE
A52: 5459 | B52: Magda B | F52: BRAK TELEFONU | G52: UZUPELNIC DANE
A53: 5459 | B53: Magda B | F53: BRAK STATUSU | G53: UZUPELNIC DANE
...

Sheet EXECUTIVE_BRIEF
A1: EXECUTIVE BRIEF
A2: Codzienny raport właściciela — sprzedaż, follow-upy, ryzyka.
A4: EXECUTIVE DAILY BRIEF PRO | 2026-06-10 15:30
A6: SEKCJA 1 | FINANSE
A7: PIPELINE | B7: 3487048 | C7: Aktywne oferty
A8: FORECAST | B8: 382100 | C8: Wazony forecast
A9: SPRZEDAZ MIESIACA | B9: 511825.12 | C9: Suma Magda K + Magda B
A10: SREDNIA WARTOSC OFERTY | B10: 25712.01 | C10: CRM_MAGDY
A11: WARTOSC ZAGROZONEGO PIPELINE | B11: 2837748 | C11: Pozary A + B
A13: SEKCJA 2 | ZESPOL
A14: Handlowiec | B14: Sprzedaz | C14: Premia | D14: Pozary A | E14: Pozary B | F14: Zalegle follow-upy
A15: Magda K | B15: 290418 | C15: 5308.36 | D15: 14 | E15: 40 | F15: 0
A16: Magda B | B16: 221407.12 | C16: 3928.14 | D16: 11 | E16: 32 | F16: 0
A18: SEKCJA 3 | POZARY SPRZEDAZOWE
A19: POZARY A | B19: 25 | C19: Krytyczne
A20: POZARY B | B20: 73 | C20: Wysokie ryzyko
A21: LACZNA WARTOSC POZAROW | B21: 2837748 | C21: TOP i reszta A/B
A22: TOP 10 NAJWIEKSZYCH POZAROW
A23: klient | B23: nr oferty | C23: opiekun | D23: kwota | E23: dni od ostatniej akcji | F23: priorytet
A24: BRAK NAZWY KLIENTA | B24: 5614 | D24: 105000 | E24: 42 | F24: A
A25: BRAK NAZWY KLIENTA | B25: 5535 | D25: 90000 | E25: 96 | F25: A
A26: BRAK NAZWY KLIENTA | B26: 5572 | D26: 60000 | E26: 70 | F26: A
A27: BRAK NAZWY KLIENTA | B27: 5581 | D27: 60000 | E27: 62 | F27: A
A28: BRAK NAZWY KLIENTA | B28: 5644 | D28: 56000 | E28: 9 | F28: B
A29: BRAK NAZWY KLIENTA | B29: 5557 | D29: 51200 | E29: 78 | F29: A
A30: BRAK NAZWY KLIENTA | B30: 5466 | D30: 50000 | E30: 145 | F30: A
A31: BRAK NAZWY KLIENTA | B31: 5651 | D31: 49000 | E31: 8 | F31: B
A32: BRAK NAZWY KLIENTA | B32: 5646 | D32: 48000 | E32: 9 | F32: B
A33: BRAK NAZWY KLIENTA | B33: 5539 | D33: 41000 | E33: 92 | F33: A
A35: SEKCJA 4 | FOLLOW-UP CONTROL
A36: FOLLOW-UP 3D | B36: 156 | C36: Liczba zadan
A37: FOLLOW-UP 7D | B37: 176 | C37: Liczba zadan
A38: FOLLOW-UP 30D | B38: 202 | C38: Liczba zadan
A39: REAKTYWACJE 90D | B39: 113 | C39: Liczba zadan
A40: LACZNIE OTWARTE ZADANIA | B40: 0 | C40: Wszystkie otwarte
A42: SEKCJA 5 | JAKOSC CRM
A43: SREDNIA JAKOSC CRM | B43: 0 | C43: Srednia procentowa
A44: LICZBA REKORDOW Z BRAKAMI | B44: 1057 | C44: Min. jeden brak
A45: BRAK TELEFONU | B45: 1057 | C45: CRM_MAGDY
A46: BRAK KWOTY | B46: 876 | C46: CRM_MAGDY
...

Sheet MAGDA_SCOREBOARD
A1: OBSŁUGA
A2: MAGDA K
A3: MAGDA B | B3: 0 | C3: 0 | D3: 0.01 | E3: 0 | F3: 0 | G3: 0 | H3: 0 | I3: 0
A4: HANDLOWIEC | B4: SPRZEDAZ NETTO | C4: SPRZEDANE SZTUKI | D4: PREMIA % | E4: PREMIA PROCENTOWA | F4: BONUS SZTUKI | G4: BONUS JAKOSC CRM | H4: KARA FOLLOW-UP | I4: KARA POZARY A | J4: KARA POZARY B | K4: PREMIA RAZEM | L4: PIPELINE | M4: FORECAST | N4: JAKOSC CRM % | O4: ZALEGLE FOLLOW-UPY | P4: POZARY A | Q4: POZARY B
A5: MAGDA K | B5: 290418 | C5: 11 | D5: 0.02 | E5: 5808.36 | F5: 1000 | G5: 0 | H5: 0 | I5: -1000 | J5: -500 | K5: 5308.36 | L5: 1801200 | M5: 18000 | N5: 59.82 | O5: 0 | P5: 14 | Q5: 40
A6: MAGDA B | B6: 221407.12 | C6: 12 | D6: 0.02 | E6: 4428.14 | F6: 1000 | G6: 0 | H6: 0 | I6: -1000 | J6: -500 | K6: 3928.14 | L6: 1685848 | M6: 364100 | N6: 56.51 | O6: 0 | P6: 11 | Q6: 32
A8: POZARY MAGDA K | B8: 54
A9: POZARY MAGDA B | B9: 43
A10: WARTOSC ZAGROZONEGO PIPELINE | B10: 2810748

Sheet _SYNC_CACHE
A1: NIE EDYTUJ — SYSTEM ADEZO OS | Z1: NIE EDYTUJ — ZAKŁADKA SYSTEMOWA ADEZO OS 2.0
A2: Zakładka techniczna. Nie edytuj.
A4: SYNC_ID | B4: SYNC_DATE | C4: DATA ZAPYTANIA | D4: DATA OFERTY | E4: DATA OSTATNIEJ AKCJI | F4: DATA KOLEJNEGO KONTAKTU | G4: KLIENT | H4: E-MAIL | I4: TELEFON | J4: NR OFERTY | K4: OBSŁUGA | L4: ŹRÓDŁO | M4: KWOTA | N4: SZANSA % | O4: KAMIEŃ MILOWY | P4: STATUS | Q4: DATA SPRZEDAŻY | R4: SPRZEDAŻ NETTO | S4: SPRZEDANE SZTUKI | T4: MIEJSCOWOŚĆ | U4: POWÓD ODRZUCENIA | V4: NOTATKI | W4: DNI OD AKCJI | X4: JAKOŚĆ CRM % | Y4: SYGNAŁ OS | Z4: KOLUMNA_26
A5: CRM-00001 | B5: 46182 | C5: 46014 | D5: 46024 | E5: 46024 | J5: 5443 | K5: Magda K | L5: MAIL | M5: 28000 | O5: follow up | T5: Wrocław
A6: CRM-00002 | B6: 46182 | C6: 46024 | D6: 0-01-2026 | E6: 46024 | J6: 5444 | K6: Magda K | L6: FACEBOOK | M6: 26622 | O6: zamówienie | P6: WYGRANA | Q6: 46163 | R6: 26622 | S6: 1 | T6: Borzechów
A7: CRM-00003 | B7: 46182 | C7: 46024 | D7: 46024 | E7: 46024 | F7: instagram pejtiiii | J7: 5445 | K7: Magda K | L7: INSTAGRAM | M7: 23000 | O7: follow up | P7: PRZEGRANA | T7: Stara Niedziałka 05-300 | U7: nie odpowiada
A8: CRM-00004 | B8: 46182 | C8: 46026 | D8: 46027 | E8: 46027 | J8: 5446 | K8: Magda K | L8: MAIL | O8: follow up | P8: PRZEGRANA | U8: nie odpowiada
A9: CRM-00005 | B9: 46182 | C9: 46027 | D9: 46027 | E9: 46027 | J9: 5447 | K9: Magda K | L9: MAIL | M9: 21000 | O9: follow up | P9: PRZEGRANA | T9: Lubiszew Tczewski | U9: nie odpowiada
A10: CRM-00006 | B10: 46182 | C10: 46023 | D10: 46027 | E10: 46027 | J10: 5448 | K10: Magda K | L10: INSTAGRAM | M10: 23000 | O10: follow up | P10: PRZEGRANA | T10: Tarchały Wielkie | U10: nie odpowiada
A11: CRM-00007 | B11: 46182 | C11: 46013 | D11: 46029 | E11: 46029 | J11: 5449 | K11: Magda K | L11: FACEBOOK | M11: 20500 | O11: follow up | P11: PRZEGRANA | T11: Łososina Dolna | U11: nie odpowiada
A12: CRM-00008 | B12: 46182 | C12: 46027 | D12: 46029 | E12: 46029 | J12: 5450 | K12: Magda K | L12: FACEBOOK | M12: 29000 | O12: follow up | P12: PRZEGRANA | T12: Tarnowo podgórne | U12: nie odpowiada
A13: CRM-00009 | B13: 46182 | C13: 46027 | D13: 46029 | E13: 46029 | J13: 5451 | K13: Magda K | L13: FACEBOOK | M13: 21000 | O13: follow up | P13: PRZEGRANA | T13: Nowe Rybie | U13: nie odpowiada
A14: CRM-00010 | B14: 46182 | C14: 46027 | D14: 46030 | E14: 46030 | J14: 5452 | K14: Magda K | L14: MAIL | M14: 23000 | O14: oferta | P14: PRZEGRANA | T14: Bielsko Biała | U14: nie odpowiada
A15: CRM-00011 | B15: 46182 | C15: 46031 | D15: 46031 | E15: 46031 | F15: salon | J15: 5453 | K15: Magda B | L15: MAIL
A16: CRM-00012 | B16: 46182 | C16: 46034 | D16: 46034 | E16: 46034 | J16: 5454 | K16: Magda K | L16: FORMULARZ | M16: 23000 | O16: wstępne rozmowy | P16: PRZEGRANA | U16: nie odpowiada
A17: CRM-00013 | B17: 46182 | C17: 46034 | D17: 46034 | E17: 46034 | J17: 5455 | K17: Magda B | L17: MAIL | M17: 23000 | O17: oferta
A18: CRM-00014 | B18: 46182 | C18: 46034 | D18: 46034 | E18: 46034 | J18: 5456 | K18: Magda K | L18: MAIL | M18: 20196 | N18: 1 | O18: realizacja | P18: WYGRANA | Q18: 46162 | R18: 20196 | S18: 1 | T18: Krakó
A19: CRM-00015 | B19: 46182 | C19: 46035 | D19: 46035 | E19: 46035 | J19: 5457 | K19: Magda K | L19: MAIL | M19: 21000 | O19: follow up | T19: Głodowo | U19: wysoka cena
A20: CRM-00016 | B20: 46182 | C20: 46035 | D20: 46035 | E20: 46035 | J20: 5458 | K20: Magda B | L20: MAIL | M20: 18252 | O20: realizacja | P20: WYGRANA | R20: 18252 | S20: 1
A21: CRM-00017 | B21: 46182 | C21: 46036 | D21: 46036 | E21: 46036 | F21: Józef Żurek | J21: 5459 | K21: Magda B | L21: MAIL | M21: 25000 | O21: oferta
A22: CRM-00018 | B22: 46182 | C22: 46036 | D22: 46036 | E22: 46036 | J22: 5460 | K22: Magda B | L22: MAIL | M22: 20000 | O22: oferta
A23: CRM-00019 | B23: 46182 | C23: 46037 | D23: 46037 | E23: 46037 | J23: 5461 | K23: Magda K | L23: FACEBOOK | M23: 23000 | O23: follow up | P23: PRZEGRANA | T23: Podłęże | U23: nie odpowiada
A24: CRM-00020 | B24: 46182 | C24: 46037 | D24: 46037 | E24: 46037 | J24: 5462 | K24: Magda K | L24: FACEBOOK | M24: 22000 | O24: follow up | P24: PRZEGRANA | U24: nie odpowiada
A25: CRM-00021 | B25: 46182 | C25: 45307 | D25: 46038 | E25: 46038 | J25: 5463 | K25: Magda B | L25: MAIL | M25: 25100 | O25: oferta | T25: Rzeszów
A26: CRM-00022 | B26: 46182 | C26: 46038 | D26: 46038 | E26: 46038 | F26: czekamy na miejscowosc | J26: 5464 | K26: Magda K | L26: MAIL | M26: 12500 | O26: widełki cenowe | P26: PRZEGRANA | U26: nie odpowiada
A27: CRM-00023 | B27: 46182 | C27: 46038 | D27: 46038 | E27: 46038 | F27: bedzie zamawiac, czekaja na wylewki | J27: 5465 | K27: Magda K | L27: MAIL | M27: 25600 | O27: decyzja na tak | P27: WYGRANA | R27: 25600 | S27: 1 | T27: Grabowo 07-415
A28: CRM-00024 | B28: 46182 | C28: 46038 | D28: 46038 | E28: 46038 | J28: 5466 | K28: Magda B | L28: TELEFON | M28: 50000 | O28: oferta | T28: Konstancin Jeziorna
A29: CRM-00025 | B29: 46182 | C29: 46038 | D29: 46038 | E29: 46038 | J29: 5467 | K29: Magda B | L29: FORMULARZ | M29: 12000 | O29: widełki cenowe
A30: CRM-00026 | B30: 46182 | C30: 46041 | D30: 46041 | E30: 46041 | J30: 5468 | K30: Magda B | L30: MAIL | M30: 20000 | O30: oferta | T30: Holandia
A31: CRM-00027 | B31: 46182 | C31: 46041 | D31: 46041 | E31: 46041 | J31: 5469 | K31: Magda B | L31: FORMULARZ | M31: 25000 | O31: oferta | T31: Częstochowa
A32: CRM-00028 | B32: 46182 | C32: 46041 | D32: 46041 | E32: 46041 | J32: 5470 | K32: Magda B | L32: WIZYTA OSOBISTA | M32: 14000 | O32: zamówienie | P32: WYGRANA | R32: 14000 | S32: 1 | T32: Bielsko - Biała
A33: CRM-00029 | B33: 46182 | C33: 46041 | D33: 46042 | E33: 46042 | J33: 5471 | K33: Magda K | L33: MAIL | M33: 25000 | O33: follow up | P33: PRZEGRANA | T33: Pruszków | U33: nie odpowiada
A34: CRM-00030 | B34: 46182 | C34: 46041 | D34: 46042 | E34: 46042 | J34: 5472 | K34: Magda K | L34: MAIL | M34: 23000 | O34: follow up | P34: PRZEGRANA | T34: Zakliczyn kolo Myslenic | U34: nie odpowiada
A35: CRM-00031 | B35: 46182 | C35: 46042 | D35: 46042 | E35: 46042 | F35: dostawa | J35: 5473 | K35: Magda K | L35: MAIL | M35: 25000 | O35: follow up | P35: PRZEGRANA | T35: Tczew | U35: nie odpowiada
A36: CRM-00032 | B36: 46182 | C36: 46034 | D36: 46043 | E36: 46043 | J36: 5474 | K36: Magda K | L36: MAIL | M36: 23000 | O36: follow up | P36: PRZEGRANA | T36: Jakubowice Koninskie | U36: nie odpowiada
A37: CRM-00033 | B37: 46182 | C37: 46027 | D37: 46043 | E37: 46043 | J37: 5475 | K37: Magda K | L37: MAIL | M37: 26000 | O37: oferta | P37: PRZEGRANA | T37: Lubiszewo Tczewskie | U37: nie odpowiada
A38: CRM-00034 | B38: 46182 | C38: 46044 | D38: 46045 | E38: 46045 | F38: kupiła baranskiego | J38: 5476 | K38: Magda K | L38: MAIL | M38: 19000 | O38: follow up | P38: PRZEGRANA | T38: Wyszków | U38: wysoka cena
A39: CRM-00035 | B39: 46182 | C39: 46042 | D39: 46045 | E39: 46045 | F39: budzet 17 000 zł, wysłana wersja ekonomiczna | J39: 5477 | K39: Magda K | L39: MAIL | M39: 23000 | O39: follow up | P39: PRZEGRANA | T39: Krosno | U39: nie odpowiada
A40: CRM-00036 | B40: 46182 | C40: 45680 | D40: 45680 | E40: 45680 | F40: będzie zamawiał czeka na wylewki | J40: 5478 | K40: Magda B | L40: TELEFON | M40: 30000 | O40: oferta | T40: Rzeszów
A41: CRM-00037 | B41: 46182 | C41: 46048 | D41: 46048 | E41: 46048 | J41: 5479 | K41: Magda B | L41: FORMULARZ | M41: 25000 | O41: oferta
...

Sheet _FORECAST_CALC
A1: NIE EDYTUJ — SYSTEM ADEZO OS
A2: Ważony forecast: kwota × szansa. Nie edytuj.
A4: SYNC_ID | B4: KLIENT | C4: NR OFERTY | D4: OBSŁUGA | E4: KWOTA | F4: SZANSA % | G4: STATUS | H4: KAMIEŃ MILOWY | I4: WAŻONY FORECAST | J4: KATEGORIA
A5: =IF(CRM_MAGDY!H5="","","CRM-"&TEXT(ROW()-4,"0000")) -> CRM-0001 | B5: =CRM_MAGDY!E5 -> 0 | C5: =CRM_MAGDY!H5 -> 5443 | D5: =CRM_MAGDY!I5 -> Magda K | E5: =IFERROR(VALUE(CRM_MAGDY!K5),0) -> 28000 | F5: =IFERROR(IF(CRM_MAGDY!L5>1,CRM_MAGDY!L5/100,CRM_MAGDY!L5),0) -> 0 | G5: =CRM_MAGDY!N5 -> 0 | H5: =CRM_MAGDY!M5 -> follow up | I5: =IF(OR(G5="WYGRANA",G5="PRZEGRANA"),0,E5*F5) -> 0 | J5: =IF(F5>=0.7,"PEWNY",IF(F5>=0.3,"REALNY","POTENCJAŁ")) -> POTENCJAŁ
A6: =IF(CRM_MAGDY!H6="","","CRM-"&TEXT(ROW()-4,"0000")) -> CRM-0002 | B6: =CRM_MAGDY!E6 -> 0 | C6: =CRM_MAGDY!H6 -> 5444 | D6: =CRM_MAGDY!I6 -> Magda K | E6: =IFERROR(VALUE(CRM_MAGDY!K6),0) -> 26622 | F6: =IFERROR(IF(CRM_MAGDY!L6>1,CRM_MAGDY!L6/100,CRM_MAGDY!L6),0) -> 1 | G6: =CRM_MAGDY!N6 -> WYGRANA | H6: =CRM_MAGDY!M6 -> zamówienie | I6: =IF(OR(G6="WYGRANA",G6="PRZEGRANA"),0,E6*F6) -> 0 | J6: =IF(F6>=0.7,"PEWNY",IF(F6>=0.3,"REALNY","POTENCJAŁ")) -> PEWNY
A7: =IF(CRM_MAGDY!H7="","","CRM-"&TEXT(ROW()-4,"0000")) -> CRM-0003 | B7: =CRM_MAGDY!E7 -> 0 | C7: =CRM_MAGDY!H7 -> 5445 | D7: =CRM_MAGDY!I7 -> Magda K | E7: =IFERROR(VALUE(CRM_MAGDY!K7),0) -> 23000 | F7: =IFERROR(IF(CRM_MAGDY!L7>1,CRM_MAGDY!L7/100,CRM_MAGDY!L7),0) -> 0 | G7: =CRM_MAGDY!N7 -> PRZEGRANA | H7: =CRM_MAGDY!M7 -> follow up | I7: =IF(OR(G7="WYGRANA",G7="PRZEGRANA"),0,E7*F7) -> 0 | J7: =IF(F7>=0.7,"PEWNY",IF(F7>=0.3,"REALNY","POTENCJAŁ")) -> POTENCJAŁ
A8: =IF(CRM_MAGDY!H8="","","CRM-"&TEXT(ROW()-4,"0000")) -> CRM-0004 | B8: =CRM_MAGDY!E8 -> 0 | C8: =CRM_MAGDY!H8 -> 5446 | D8: =CRM_MAGDY!I8 -> Magda K | E8: =IFERROR(VALUE(CRM_MAGDY!K8),0) -> 0 | F8: =IFERROR(IF(CRM_MAGDY!L8>1,CRM_MAGDY!L8/100,CRM_MAGDY!L8),0) -> 0 | G8: =CRM_MAGDY!N8 -> PRZEGRANA | H8: =CRM_MAGDY!M8 -> follow up | I8: =IF(OR(G8="WYGRANA",G8="PRZEGRANA"),0,E8*F8) -> 0 | J8: =IF(F8>=0.7,"PEWNY",IF(F8>=0.3,"REALNY","POTENCJAŁ")) -> POTENCJAŁ
A9: =IF(CRM_MAGDY!H9="","","CRM-"&TEXT(ROW()-4,"0000")) -> CRM-0005 | B9: =CRM_MAGDY!E9 -> 0 | C9: =CRM_MAGDY!H9 -> 5447 | D9: =CRM_MAGDY!I9 -> Magda K | E9: =IFERROR(VALUE(CRM_MAGDY!K9),0) -> 21000 | F9: =IFERROR(IF(CRM_MAGDY!L9>1,CRM_MAGDY!L9/100,CRM_MAGDY!L9),0) -> 0 | G9: =CRM_MAGDY!N9 -> PRZEGRANA | H9: =CRM_MAGDY!M9 -> follow up | I9: =IF(OR(G9="WYGRANA",G9="PRZEGRANA"),0,E9*F9) -> 0 | J9: =IF(F9>=0.7,"PEWNY",IF(F9>=0.3,"REALNY","POTENCJAŁ")) -> POTENCJAŁ
A10: =IF(CRM_MAGDY!H10="","","CRM-"&TEXT(ROW()-4,"0000")) -> CRM-0006 | B10: =CRM_MAGDY!E10 -> 0 | C10: =CRM_MAGDY!H10 -> 5448 | D10: =CRM_MAGDY!I10 -> Magda K | E10: =IFERROR(VALUE(CRM_MAGDY!K10),0) -> 23000 | F10: =IFERROR(IF(CRM_MAGDY!L10>1,CRM_MAGDY!L10/100,CRM_MAGDY!L10),0) -> 0 | G10: =CRM_MAGDY!N10 -> PRZEGRANA | H10: =CRM_MAGDY!M10 -> follow up | I10: =IF(OR(G10="WYGRANA",G10="PRZEGRANA"),0,E10*F10) -> 0 | J10: =IF(F10>=0.7,"PEWNY",IF(F10>=0.3,"REALNY","POTENCJAŁ")) -> POTENCJAŁ
A11: =IF(CRM_MAGDY!H11="","","CRM-"&TEXT(ROW()-4,"0000")) -> CRM-0007 | B11: =CRM_MAGDY!E11 -> 0 | C11: =CRM_MAGDY!H11 -> 5449 | D11: =CRM_MAGDY!I11 -> Magda K | E11: =IFERROR(VALUE(CRM_MAGDY!K11),0) -> 20500 | F11: =IFERROR(IF(CRM_MAGDY!L11>1,CRM_MAGDY!L11/100,CRM_MAGDY!L11),0) -> 0 | G11: =CRM_MAGDY!N11 -> PRZEGRANA | H11: =CRM_MAGDY!M11 -> follow up | I11: =IF(OR(G11="WYGRANA",G11="PRZEGRANA"),0,E11*F11) -> 0 | J11: =IF(F11>=0.7,"PEWNY",IF(F11>=0.3,"REALNY","POTENCJAŁ")) -> POTENCJAŁ
A12: =IF(CRM_MAGDY!H12="","","CRM-"&TEXT(ROW()-4,"0000")) -> CRM-0008 | B12: =CRM_MAGDY!E12 -> 0 | C12: =CRM_MAGDY!H12 -> 5450 | D12: =CRM_MAGDY!I12 -> Magda K | E12: =IFERROR(VALUE(CRM_MAGDY!K12),0) -> 29000 | F12: =IFERROR(IF(CRM_MAGDY!L12>1,CRM_MAGDY!L12/100,CRM_MAGDY!L12),0) -> 0 | G12: =CRM_MAGDY!N12 -> PRZEGRANA | H12: =CRM_MAGDY!M12 -> follow up | I12: =IF(OR(G12="WYGRANA",G12="PRZEGRANA"),0,E12*F12) -> 0 | J12: =IF(F12>=0.7,"PEWNY",IF(F12>=0.3,"REALNY","POTENCJAŁ")) -> POTENCJAŁ
A13: =IF(CRM_MAGDY!H13="","","CRM-"&TEXT(ROW()-4,"0000")) -> CRM-0009 | B13: =CRM_MAGDY!E13 -> 0 | C13: =CRM_MAGDY!H13 -> 5451 | D13: =CRM_MAGDY!I13 -> Magda K | E13: =IFERROR(VALUE(CRM_MAGDY!K13),0) -> 21000 | F13: =IFERROR(IF(CRM_MAGDY!L13>1,CRM_MAGDY!L13/100,CRM_MAGDY!L13),0) -> 0 | G13: =CRM_MAGDY!N13 -> PRZEGRANA | H13: =CRM_MAGDY!M13 -> follow up | I13: =IF(OR(G13="WYGRANA",G13="PRZEGRANA"),0,E13*F13) -> 0 | J13: =IF(F13>=0.7,"PEWNY",IF(F13>=0.3,"REALNY","POTENCJAŁ")) -> POTENCJAŁ
A14: =IF(CRM_MAGDY!H14="","","CRM-"&TEXT(ROW()-4,"0000")) -> CRM-0010 | B14: =CRM_MAGDY!E14 -> 0 | C14: =CRM_MAGDY!H14 -> 5452 | D14: =CRM_MAGDY!I14 -> Magda K | E14: =IFERROR(VALUE(CRM_MAGDY!K14),0) -> 23000 | F14: =IFERROR(IF(CRM_MAGDY!L14>1,CRM_MAGDY!L14/100,CRM_MAGDY!L14),0) -> 0 | G14: =CRM_MAGDY!N14 -> PRZEGRANA | H14: =CRM_MAGDY!M14 -> oferta | I14: =IF(OR(G14="WYGRANA",G14="PRZEGRANA"),0,E14*F14) -> 0 | J14: =IF(F14>=0.7,"PEWNY",IF(F14>=0.3,"REALNY","POTENCJAŁ")) -> POTENCJAŁ
A15: =IF(CRM_MAGDY!H15="","","CRM-"&TEXT(ROW()-4,"0000")) -> CRM-0011 | B15: =CRM_MAGDY!E15 -> 0 | C15: =CRM_MAGDY!H15 -> 5453 | D15: =CRM_MAGDY!I15 -> Magda B | E15: =IFERROR(VALUE(CRM_MAGDY!K15),0) -> 0 | F15: =IFERROR(IF(CRM_MAGDY!L15>1,CRM_MAGDY!L15/100,CRM_MAGDY!L15),0) -> 0 | G15: =CRM_MAGDY!N15 -> 0 | H15: =CRM_MAGDY!M15 -> 0 | I15: =IF(OR(G15="WYGRANA",G15="PRZEGRANA"),0,E15*F15) -> 0 | J15: =IF(F15>=0.7,"PEWNY",IF(F15>=0.3,"REALNY","POTENCJAŁ")) -> POTENCJAŁ
A16: =IF(CRM_MAGDY!H16="","","CRM-"&TEXT(ROW()-4,"0000")) -> CRM-0012 | B16: =CRM_MAGDY!E16 -> 0 | C16: =CRM_MAGDY!H16 -> 5454 | D16: =CRM_MAGDY!I16 -> Magda K | E16: =IFERROR(VALUE(CRM_MAGDY!K16),0) -> 23000 | F16: =IFERROR(IF(CRM_MAGDY!L16>1,CRM_MAGDY!L16/100,CRM_MAGDY!L16),0) -> 0 | G16: =CRM_MAGDY!N16 -> PRZEGRANA | H16: =CRM_MAGDY!M16 -> wstępne rozmowy | I16: =IF(OR(G16="WYGRANA",G16="PRZEGRANA"),0,E16*F16) -> 0 | J16: =IF(F16>=0.7,"PEWNY",IF(F16>=0.3,"REALNY","POTENCJAŁ")) -> POTENCJAŁ
... A1200: =IF(CRM_MAGDY!H1200="","","CRM-"&TEXT(ROW()-4,"0000")) | B1200: =CRM_MAGDY!E1200 -> 0 | C1200: =CRM_MAGDY!H1200 -> 0 | D1200: =CRM_MAGDY!I1200 -> 0 | E1200: =IFERROR(VALUE(CRM_MAGDY!K1200),0) -> 0 | F1200: =IFERROR(IF(CRM_MAGDY!L1200>1,CRM_MAGDY!L1200/100,CRM_MAGDY!L1200),0) -> 0 | G1200: =CRM_MAGDY!N1200 -> 0 | H1200: =CRM_MAGDY!M1200 -> 0 | I1200: =IF(OR(G1200="WYGRANA",G1200="PRZEGRANA"),0,E1200*F1200) -> 0 | J1200: =IF(F1200>=0.7,"PEWNY",IF(F1200>=0.3,"REALNY","POTENCJAŁ")) -> POTENCJAŁ

Sheet _OS_TASKS
A1: NIE EDYTUJ — SYSTEM ADEZO OS | K1: NIE EDYTUJ — ZAKŁADKA SYSTEMOWA ADEZO OS 2.0
A2: Automatyczna lista zadań. Nie edytuj źródłowo.
A4: TASK_ID | B4: SYNC_ID | C4: TERMIN | D4: OBSŁUGA | E4: KLIENT | F4: NR OFERTY | G4: TYP ZADANIA | H4: PRIORYTET | I4: STATUS ZADANIA | J4: KOMUNIKAT | K4: KOLUMNA_11
A5: T-00001 | B5: CRM-00001 | C5: 46182 | D5: Magda K | E5: Wrocław | F5: 5443 | G5: BRAK_STATUSU | H5: WYSOKI | I5: DO ZROBIENIA | J5: Uzupełnij status.
A6: T-00002 | B6: CRM-00001 | C6: 46182 | D6: Magda K | E6: Wrocław | F6: 5443 | G6: BRAK_SZANSY | H6: ŚREDNI | I6: DO ZROBIENIA | J6: Uzupełnij szansę sprzedaży.
A7: T-00003 | B7: CRM-00001 | C7: 46182 | D7: Magda K | E7: Wrocław | F7: 5443 | G7: REAKTYWACJA_90D | H7: KRYTYCZNY | I7: DO ZROBIENIA | J7: Zimny lead — reaktywacja albo zamknięcie.
A8: T-00004 | B8: CRM-00011 | C8: 46182 | D8: Magda B | E8: (brak klienta) | F8: 5453 | G8: BRAK_KWOTY | H8: WYSOKI | I8: DO ZROBIENIA | J8: Uzupełnij kwotę oferty.
A9: T-00005 | B9: CRM-00011 | C9: 46182 | D9: Magda B | E9: (brak klienta) | F9: 5453 | G9: BRAK_STATUSU | H9: WYSOKI | I9: DO ZROBIENIA | J9: Uzupełnij status.
A10: T-00006 | B10: CRM-00011 | C10: 46182 | D10: Magda B | E10: (brak klienta) | F10: 5453 | G10: BRAK_SZANSY | H10: ŚREDNI | I10: DO ZROBIENIA | J10: Uzupełnij szansę sprzedaży.
A11: T-00007 | B11: CRM-00011 | C11: 46182 | D11: Magda B | E11: (brak klienta) | F11: 5453 | G11: REAKTYWACJA_90D | H11: KRYTYCZNY | I11: DO ZROBIENIA | J11: Zimny lead — reaktywacja albo zamknięcie.
A12: T-00008 | B12: CRM-00013 | C12: 46182 | D12: Magda B | E12: (brak klienta) | F12: 5455 | G12: BRAK_STATUSU | H12: WYSOKI | I12: DO ZROBIENIA | J12: Uzupełnij status.
A13: T-00009 | B13: CRM-00013 | C13: 46182 | D13: Magda B | E13: (brak klienta) | F13: 5455 | G13: BRAK_SZANSY | H13: ŚREDNI | I13: DO ZROBIENIA | J13: Uzupełnij szansę sprzedaży.
A14: T-00010 | B14: CRM-00013 | C14: 46182 | D14: Magda B | E14: (brak klienta) | F14: 5455 | G14: REAKTYWACJA_90D | H14: KRYTYCZNY | I14: DO ZROBIENIA | J14: Zimny lead — reaktywacja albo zamknięcie.
A15: T-00011 | B15: CRM-00015 | C15: 46182 | D15: Magda K | E15: Głodowo | F15: 5457 | G15: BRAK_STATUSU | H15: WYSOKI | I15: DO ZROBIENIA | J15: Uzupełnij status.
A16: T-00012 | B16: CRM-00015 | C16: 46182 | D16: Magda K | E16: Głodowo | F16: 5457 | G16: BRAK_SZANSY | H16: ŚREDNI | I16: DO ZROBIENIA | J16: Uzupełnij szansę sprzedaży.
... A4392: T-01993 | B4392: CRM-01057 | C4392: 46183 | D4392: Magda K | E4392: Jarosław Malinowski | F4392: 5315 | G4392: REAKTYWACJA 90D | H4392: KRYTYCZNY | I4392: DO ZROBIENIA | J4392: Automat: REAKTYWACJA 90D | dni od akcji: 258

Sheet _ALERTS_LOG
A1: NIE EDYTUJ — SYSTEM ADEZO OS | K1: NIE EDYTUJ — ZAKŁADKA SYSTEMOWA ADEZO OS 2.0
A2: Rejestr alertów zarządczych. Nie edytuj.
A4: ALERT_ID | B4: DATA ALERTU | C4: SYNC_ID | D4: OBSŁUGA | E4: KLIENT | F4: NR OFERTY | G4: TYP ALERTU | H4: WAGA | I4: STATUS | J4: KOMUNIKAT | K4: KOLUMNA_11
A5: A-00001 | B5: 46182 | C5: CRM-00001 | D5: Magda K | E5: Wrocław | F5: 5443 | G5: BRAK_STATUSU | H5: WYSOKA | I5: NOWY | J5: Brak statusu utrudnia kontrolę pipeline.
A6: A-00002 | B6: 46182 | C6: CRM-00001 | D6: Magda K | E6: Wrocław | F6: 5443 | G6: REAKTYWACJA_90D | H6: KRYTYCZNA | I6: NOWY | J6: Brak kontaktu 158 dni.
A7: A-00003 | B7: 46182 | C7: CRM-00011 | D7: Magda B | E7: (brak klienta) | F7: 5453 | G7: BRAK_KWOTY | H7: WYSOKA | I7: NOWY | J7: Oferta bez kwoty blokuje forecast.
A8: A-00004 | B8: 46182 | C8: CRM-00011 | D8: Magda B | E8: (brak klienta) | F8: 5453 | G8: BRAK_STATUSU | H8: WYSOKA | I8: NOWY | J8: Brak statusu utrudnia kontrolę pipeline.
A9: A-00005 | B9: 46182 | C9: CRM-00011 | D9: Magda B | E9: (brak klienta) | F9: 5453 | G9: REAKTYWACJA_90D | H9: KRYTYCZNA | I9: NOWY | J9: Brak kontaktu 151 dni.
A10: A-00006 | B10: 46182 | C10: CRM-00013 | D10: Magda B | E10: (brak klienta) | F10: 5455 | G10: BRAK_STATUSU | H10: WYSOKA | I10: NOWY | J10: Brak statusu utrudnia kontrolę pipeline.
A11: A-00007 | B11: 46182 | C11: CRM-00013 | D11: Magda B | E11: (brak klienta) | F11: 5455 | G11: REAKTYWACJA_90D | H11: KRYTYCZNA | I11: NOWY | J11: Brak kontaktu 148 dni.
A12: A-00008 | B12: 46182 | C12: CRM-00015 | D12: Magda K | E12: Głodowo | F12: 5457 | G12: BRAK_STATUSU | H12: WYSOKA | I12: NOWY | J12: Brak statusu utrudnia kontrolę pipeline.
A13: A-00009 | B13: 46182 | C13: CRM-00015 | D13: Magda K | E13: Głodowo | F13: 5457 | G13: REAKTYWACJA_90D | H13: KRYTYCZNA | I13: NOWY | J13: Brak kontaktu 147 dni.
A14: A-00010 | B14: 46182 | C14: CRM-00017 | D14: Magda B | E14: (brak klienta) | F14: 5459 | G14: BRAK_STATUSU | H14: WYSOKA | I14: NOWY | J14: Brak statusu utrudnia kontrolę pipeline.
A15: A-00011 | B15: 46182 | C15: CRM-00017 | D15: Magda B | E15: (brak klienta) | F15: 5459 | G15: REAKTYWACJA_90D | H15: KRYTYCZNA | I15: NOWY | J15: Brak kontaktu 146 dni.
A16: A-00012 | B16: 46182 | C16: CRM-00018 | D16: Magda B | E16: (brak klienta) | F16: 5460 | G16: BRAK_STATUSU | H16: WYSOKA | I16: NOWY | J16: Brak statusu utrudnia kontrolę pipeline.
... A1640: A-01636 | B1640: 46183 | C1640: CRM-00206 | D1640: Magda B | E1640: (brak klienta) | F1640: 5651 | G1640: DUŻA OFERTA BEZ KONTAKTU | H1640: KRYTYCZNA | I1640: NOWY | J1640: Kwota 49000 zl, brak kontaktu od 8 dni.

Sheet _DATA_QUALITY
A1: NIE EDYTUJ — SYSTEM ADEZO OS
A2: Kontrola kompletności danych CRM. Nie edytuj.
A4: NR OFERTY | B4: OBSŁUGA | C4: KLIENT | D4: JAKOŚĆ CRM % | E4: BRAKI | F4: SYGNAŁ OS | G4: KWOTA | H4: STATUS
A5: =CRM_MAGDY!H5 -> 5443 | B5: =CRM_MAGDY!I5 -> Magda K | C5: =CRM_MAGDY!E5 -> 0 | D5: =CRM_MAGDY!V5 -> 0 | E5: =IF(CRM_MAGDY!G5="","BRAK TELEFONU",IF(CRM_MAGDY!K5="","BRAK KWOTY",IF(CRM_MAGDY!N5="","BRAK STATUSU",IF(CRM_MAGDY!C5="","BRAK DATY AKCJI","")))) -> BRAK TELEFONU | F5: =CRM_MAGDY!W5 -> BRAKI CRM | G5: =CRM_MAGDY!K5 -> 28000 | H5: =CRM_MAGDY!N5 -> 0
A6: =CRM_MAGDY!H6 -> 5444 | B6: =CRM_MAGDY!I6 -> Magda K | C6: =CRM_MAGDY!E6 -> 0 | D6: =CRM_MAGDY!V6 -> 0.5 | E6: =IF(CRM_MAGDY!G6="","BRAK TELEFONU",IF(CRM_MAGDY!K6="","BRAK KWOTY",IF(CRM_MAGDY!N6="","BRAK STATUSU",IF(CRM_MAGDY!C6="","BRAK DATY AKCJI","")))) -> BRAK TELEFONU | F6: =CRM_MAGDY!W6 -> BRAKI CRM | G6: =CRM_MAGDY!K6 -> 26622 | H6: =CRM_MAGDY!N6 -> WYGRANA
A7: =CRM_MAGDY!H7 -> 5445 | B7: =CRM_MAGDY!I7 -> Magda K | C7: =CRM_MAGDY!E7 -> 0 | D7: =CRM_MAGDY!V7 -> 0.25 | E7: =IF(CRM_MAGDY!G7="","BRAK TELEFONU",IF(CRM_MAGDY!K7="","BRAK KWOTY",IF(CRM_MAGDY!N7="","BRAK STATUSU",IF(CRM_MAGDY!C7="","BRAK DATY AKCJI","")))) -> BRAK TELEFONU | F7: =CRM_MAGDY!W7 -> BRAKI CRM | G7: =CRM_MAGDY!K7 -> 23000 | H7: =CRM_MAGDY!N7 -> PRZEGRANA
A8: =CRM_MAGDY!H8 -> 5446 | B8: =CRM_MAGDY!I8 -> Magda K | C8: =CRM_MAGDY!E8 -> 0 | D8: =CRM_MAGDY!V8 -> 0.25 | E8: =IF(CRM_MAGDY!G8="","BRAK TELEFONU",IF(CRM_MAGDY!K8="","BRAK KWOTY",IF(CRM_MAGDY!N8="","BRAK STATUSU",IF(CRM_MAGDY!C8="","BRAK DATY AKCJI","")))) -> BRAK TELEFONU | F8: =CRM_MAGDY!W8 -> BRAKI CRM | G8: =CRM_MAGDY!K8 -> 0 | H8: =CRM_MAGDY!N8 -> PRZEGRANA
A9: =CRM_MAGDY!H9 -> 5447 | B9: =CRM_MAGDY!I9 -> Magda K | C9: =CRM_MAGDY!E9 -> 0 | D9: =CRM_MAGDY!V9 -> 0.25 | E9: =IF(CRM_MAGDY!G9="","BRAK TELEFONU",IF(CRM_MAGDY!K9="","BRAK KWOTY",IF(CRM_MAGDY!N9="","BRAK STATUSU",IF(CRM_MAGDY!C9="","BRAK DATY AKCJI","")))) -> BRAK TELEFONU | F9: =CRM_MAGDY!W9 -> BRAKI CRM | G9: =CRM_MAGDY!K9 -> 21000 | H9: =CRM_MAGDY!N9 -> PRZEGRANA
A10: =CRM_MAGDY!H10 -> 5448 | B10: =CRM_MAGDY!I10 -> Magda K | C10: =CRM_MAGDY!E10 -> 0 | D10: =CRM_MAGDY!V10 -> 0.25 | E10: =IF(CRM_MAGDY!G10="","BRAK TELEFONU",IF(CRM_MAGDY!K10="","BRAK KWOTY",IF(CRM_MAGDY!N10="","BRAK STATUSU",IF(CRM_MAGDY!C10="","BRAK DATY AKCJI","")))) -> BRAK TELEFONU | F10: =CRM_MAGDY!W10 -> BRAKI CRM | G10: =CRM_MAGDY!K10 -> 23000 | H10: =CRM_MAGDY!N10 -> PRZEGRANA
A11: =CRM_MAGDY!H11 -> 5449 | B11: =CRM_MAGDY!I11 -> Magda K | C11: =CRM_MAGDY!E11 -> 0 | D11: =CRM_MAGDY!V11 -> 0.25 | E11: =IF(CRM_MAGDY!G11="","BRAK TELEFONU",IF(CRM_MAGDY!K11="","BRAK KWOTY",IF(CRM_MAGDY!N11="","BRAK STATUSU",IF(CRM_MAGDY!C11="","BRAK DATY AKCJI","")))) -> BRAK TELEFONU | F11: =CRM_MAGDY!W11 -> BRAKI CRM | G11: =CRM_MAGDY!K11 -> 20500 | H11: =CRM_MAGDY!N11 -> PRZEGRANA
A12: =CRM_MAGDY!H12 -> 5450 | B12: =CRM_MAGDY!I12 -> Magda K | C12: =CRM_MAGDY!E12 -> 0 | D12: =CRM_MAGDY!V12 -> 0.25 | E12: =IF(CRM_MAGDY!G12="","BRAK TELEFONU",IF(CRM_MAGDY!K12="","BRAK KWOTY",IF(CRM_MAGDY!N12="","BRAK STATUSU",IF(CRM_MAGDY!C12="","BRAK DATY AKCJI","")))) -> BRAK TELEFONU | F12: =CRM_MAGDY!W12 -> BRAKI CRM | G12: =CRM_MAGDY!K12 -> 29000 | H12: =CRM_MAGDY!N12 -> PRZEGRANA
A13: =CRM_MAGDY!H13 -> 5451 | B13: =CRM_MAGDY!I13 -> Magda K | C13: =CRM_MAGDY!E13 -> 0 | D13: =CRM_MAGDY!V13 -> 0.25 | E13: =IF(CRM_MAGDY!G13="","BRAK TELEFONU",IF(CRM_MAGDY!K13="","BRAK KWOTY",IF(CRM_MAGDY!N13="","BRAK STATUSU",IF(CRM_MAGDY!C13="","BRAK DATY AKCJI","")))) -> BRAK TELEFONU | F13: =CRM_MAGDY!W13 -> BRAKI CRM | G13: =CRM_MAGDY!K13 -> 21000 | H13: =CRM_MAGDY!N13 -> PRZEGRANA
A14: =CRM_MAGDY!H14 -> 5452 | B14: =CRM_MAGDY!I14 -> Magda K | C14: =CRM_MAGDY!E14 -> 0 | D14: =CRM_MAGDY!V14 -> 0.25 | E14: =IF(CRM_MAGDY!G14="","BRAK TELEFONU",IF(CRM_MAGDY!K14="","BRAK KWOTY",IF(CRM_MAGDY!N14="","BRAK STATUSU",IF(CRM_MAGDY!C14="","BRAK DATY AKCJI","")))) -> BRAK TELEFONU | F14: =CRM_MAGDY!W14 -> BRAKI CRM | G14: =CRM_MAGDY!K14 -> 23000 | H14: =CRM_MAGDY!N14 -> PRZEGRANA
A15: =CRM_MAGDY!H15 -> 5453 | B15: =CRM_MAGDY!I15 -> Magda B | C15: =CRM_MAGDY!E15 -> 0 | D15: =CRM_MAGDY!V15 -> 0 | E15: =IF(CRM_MAGDY!G15="","BRAK TELEFONU",IF(CRM_MAGDY!K15="","BRAK KWOTY",IF(CRM_MAGDY!N15="","BRAK STATUSU",IF(CRM_MAGDY!C15="","BRAK DATY AKCJI","")))) -> BRAK TELEFONU | F15: =CRM_MAGDY!W15 -> BRAKI CRM | G15: =CRM_MAGDY!K15 -> 0 | H15: =CRM_MAGDY!N15 -> 0
A16: =CRM_MAGDY!H16 -> 5454 | B16: =CRM_MAGDY!I16 -> Magda K | C16: =CRM_MAGDY!E16 -> 0 | D16: =CRM_MAGDY!V16 -> 0.25 | E16: =IF(CRM_MAGDY!G16="","BRAK TELEFONU",IF(CRM_MAGDY!K16="","BRAK KWOTY",IF(CRM_MAGDY!N16="","BRAK STATUSU",IF(CRM_MAGDY!C16="","BRAK DATY AKCJI","")))) -> BRAK TELEFONU | F16: =CRM_MAGDY!W16 -> BRAKI CRM | G16: =CRM_MAGDY!K16 -> 23000 | H16: =CRM_MAGDY!N16 -> PRZEGRANA
... A1200: =CRM_MAGDY!H1200 -> 0 | B1200: =CRM_MAGDY!I1200 -> 0 | C1200: =CRM_MAGDY!E1200 -> 0 | D1200: =CRM_MAGDY!V1200 | E1200: =IF(CRM_MAGDY!G1200="","BRAK TELEFONU",IF(CRM_MAGDY!K1200="","BRAK KWOTY",IF(CRM_MAGDY!N1200="","BRAK STATUSU",IF(CRM_MAGDY!C1200="","BRAK DATY AKCJI","")))) -> BRAK TELEFONU | F1200: =CRM_MAGDY!W1200 | G1200: =CRM_MAGDY!K1200 -> 0 | H1200: =CRM_MAGDY!N1200 -> 0

Sheet _LISTY
A1: NIE EDYTUJ — SYSTEM ADEZO OS
A2: Słowniki do list rozwijanych — nie edytuj
A4: STATUS | B4: OBSŁUGA | C4: KAMIEŃ MILOWY | D4: SZANSA % | E4: PRIORYTET | F4: STATUS ZADANIA | G4: ŹRÓDŁO
A5: AKTYWNY | B5: Magda K | C5: nowy lead | D5: 0.1 | E5: NISKI | F5: DO ZROBIENIA | G5: MAIL
A6: OCZEKUJE | B6: Magda B | C6: wstępne rozmowy | D6: 0.25 | E6: ŚREDNI | F6: W TRAKCIE | G6: FACEBOOK
A7: WYGRANA | C7: oferta | D7: 0.5 | E7: WYSOKI | F7: ZROBIONE | G7: INSTAGRAM
A8: PRZEGRANA | C8: follow up | D8: 0.75 | E8: KRYTYCZNY | G8: FORMULARZ
C9: negocjacje | D9: 0.9 | G9: SALON
C10: zamówienie | D10: 1 | G10: POLECENIE
C11: montaż | G11: ARCHITEKT
C12: zamknięte | G12: GOOGLE ADS
G13: INNE

Sheet INSTRUKCJA
A1: INSTRUKCJA PRACY — ADEZO OS 2.0
A3: MAGDA UZUPELNIA TYLKO:
A4: - DATA OSTATNIEJ AKCJI | B4: KOLUMNA_2 | C4: KOLUMNA_3 | D4: KOLUMNA_4 | E4: KOLUMNA_5 | F4: KOLUMNA_6
A5: - DATA KOLEJNEGO KONTAKTU
A6: - STATUS
A7: - NOTATKI
A9: Nie edytowac:
A10: - Forecast
A11: - Alertow
A12: - KPI
A13: - Dashboardow
